[DEBUG] [launch.launch_context]: emitting event synchronously: 'launch.events.IncludeLaunchDescription'
[INFO] [launch]: All log files can be found below /home/will/.ros/log/2024-03-04-15-35-18-872667-will-Desktop-57583
[INFO] [launch]: Default logging verbosity is set to DEBUG
[DEBUG] [launch]: processing event: '<launch.events.include_launch_description.IncludeLaunchDescription object at 0x7f012cf057b0>'
[DEBUG] [launch]: processing event: '<launch.events.include_launch_description.IncludeLaunchDescription object at 0x7f012cf057b0>' ✓ '<launch.event_handlers.on_include_launch_description.OnIncludeLaunchDescription object at 0x7f012cf05c60>'
Starting rviz configuration


Starting nav2 launch




Starting import_webots_swarm_config

config = {'robots': {'turtlebots': [{'name': 'tb1', 'uri': '', 'translation': '-1.5 -1.5 0.015', 'orientation': [0, 0, 0, 1]}, {'name': 'tb2', 'uri': '', 'translation': '-2.5 -2.5 0.015', 'orientation': [0, 0, 0, 1]}]}, 'world_file_to_write_path': 'apartment.wbt', 'world_file_to_copy_path': '../worlds/base_worlds/apartment.wbt'}
turtlebots = [{'name': 'tb1', 'uri': '', 'translation': '-1.5 -1.5 0.015', 'orientation': [0, 0, 0, 1]}, {'name': 'tb2', 'uri': '', 'translation': '-2.5 -2.5 0.015', 'orientation': [0, 0, 0, 1]}]
[DEBUG] [launch]: An exception was raised in an async action/event
[DEBUG] [launch]: Traceback (most recent call last):
  File "/opt/ros/humble/lib/python3.10/site-packages/launch/launch_description_sources/any_launch_file_utilities.py", line 54, in get_launch_description_from_any_launch_file
    return loader(launch_file_path)
  File "/opt/ros/humble/lib/python3.10/site-packages/launch/launch_description_sources/python_launch_file_utilities.py", line 68, in get_launch_description_from_python_launch_file
    return getattr(launch_file_module, 'generate_launch_description')()
  File "/home/will/drl_swarm/install/webots_pkg/share/webots_pkg/launch/webots_nav2_no_cf_launch.py", line 160, in generate_launch_description
    swarm = import_webots_swarm_config(ROBOT_CONFIG_FILE_PATH)
  File "/home/will/drl_swarm/install/webots_pkg/share/webots_pkg/launch/webots_nav2_no_cf_launch.py", line 69, in import_webots_swarm_config
    print(f"turtlebots starting pos = {config['robots']['turtlebots'][0]['start_position']}")
KeyError: 'start_position'

The above exception was the direct cause of the following exception:

Traceback (most recent call last):
  File "/opt/ros/humble/lib/python3.10/site-packages/launch/launch_service.py", line 336, in run_async
    raise completed_tasks_exceptions[0]
  File "/opt/ros/humble/lib/python3.10/site-packages/launch/launch_service.py", line 230, in _process_one_event
    await self.__process_event(next_event)
  File "/opt/ros/humble/lib/python3.10/site-packages/launch/launch_service.py", line 250, in __process_event
    visit_all_entities_and_collect_futures(entity, self.__context))
  File "/opt/ros/humble/lib/python3.10/site-packages/launch/utilities/visit_all_entities_and_collect_futures_impl.py", line 45, in visit_all_entities_and_collect_futures
    futures_to_return += visit_all_entities_and_collect_futures(sub_entity, context)
  File "/opt/ros/humble/lib/python3.10/site-packages/launch/utilities/visit_all_entities_and_collect_futures_impl.py", line 45, in visit_all_entities_and_collect_futures
    futures_to_return += visit_all_entities_and_collect_futures(sub_entity, context)
  File "/opt/ros/humble/lib/python3.10/site-packages/launch/utilities/visit_all_entities_and_collect_futures_impl.py", line 38, in visit_all_entities_and_collect_futures
    sub_entities = entity.visit(context)
  File "/opt/ros/humble/lib/python3.10/site-packages/launch/action.py", line 108, in visit
    return self.execute(context)
  File "/opt/ros/humble/lib/python3.10/site-packages/launch/actions/include_launch_description.py", line 148, in execute
    launch_description = self.__launch_description_source.get_launch_description(context)
  File "/opt/ros/humble/lib/python3.10/site-packages/launch/launch_description_source.py", line 84, in get_launch_description
    self._get_launch_description(self.__expanded_location)
  File "/opt/ros/humble/lib/python3.10/site-packages/launch/launch_description_sources/any_launch_description_source.py", line 53, in _get_launch_description
    return get_launch_description_from_any_launch_file(location)
  File "/opt/ros/humble/lib/python3.10/site-packages/launch/launch_description_sources/any_launch_file_utilities.py", line 57, in get_launch_description_from_any_launch_file
    raise InvalidLaunchFileError(extension, likely_errors=exceptions)
launch.invalid_launch_file_error.InvalidLaunchFileError: Caught multiple exceptions when trying to load file of format [py]:
 - KeyError: 'start_position'
 - InvalidFrontendLaunchFileError: The launch file may have a syntax error, or its format is unknown

[ERROR] [launch]: Caught exception in launch (see debug for traceback): Caught multiple exceptions when trying to load file of format [py]:
 - KeyError: 'start_position'
 - InvalidFrontendLaunchFileError: The launch file may have a syntax error, or its format is unknown
[DEBUG] [launch.launch_context]: emitting event: 'launch.events.Shutdown'
[DEBUG] [launch]: processing event: '<launch.events.shutdown.Shutdown object at 0x7f012cf06500>'
[DEBUG] [launch]: processing event: '<launch.events.shutdown.Shutdown object at 0x7f012cf06500>' ✓ '<launch.event_handlers.on_shutdown.OnShutdown object at 0x7f012cf07d90>'
